Pongo solo los errores
Borrar segun se solucionen

Traceback (most recent call last):
  File "/usr/local/lib/python2.7/dist-packages/telepot/delegate.py", line 252, in wait_loop
    j.on_message(msg)
  File "/usr/local/lib/python2.7/dist-packages/telepot/helper.py", line 630, in augmented
    return handler(msg)
  File "/usr/local/lib/python2.7/dist-packages/telepot/helper.py", line 996, in on_message
    self._router.route(msg)
  File "/usr/local/lib/python2.7/dist-packages/telepot/helper.py", line 972, in route
    return fn(msg, *args, **kwargs)
  File "/usr/local/lib/python2.7/dist-packages/telepot/helper.py", line 981, in <lambda>
    'callback_query': lambda msg: self.on_callback_query(msg),
  File "./socialBot.py", line 149, in on_callback_query
    self.loc = [option[1], option[2]]
IndexError: list index out of range

Traceback (most recent call last):
  File "/usr/local/lib/python2.7/dist-packages/telepot/delegate.py", line 252, in wait_loop
    j.on_message(msg)
  File "/usr/local/lib/python2.7/dist-packages/telepot/helper.py", line 630, in augmented
    return handler(msg)
  File "/usr/local/lib/python2.7/dist-packages/telepot/helper.py", line 996, in on_message
    self._router.route(msg)
  File "/usr/local/lib/python2.7/dist-packages/telepot/helper.py", line 972, in route
    return fn(msg, *args, **kwargs)
  File "/usr/local/lib/python2.7/dist-packages/telepot/helper.py", line 981, in <lambda>
    'callback_query': lambda msg: self.on_callback_query(msg),
  File "./socialBot.py", line 174, in on_callback_query
    bot.sendPhoto(from_id, info['photos'][int(query_data)], reply_markup=keyboards.photos(info, int(query_data)))
ValueError: invalid literal for int() with base 10: 'init'
ERROR:root:on_close() called due to ValueError: invalid literal for int() with base 10: 'init'








